<?xml version="1.0"?>
<robot name="diff_drive_robot">

  <link name="base_footprint"/>

  <link name="base_link">
    <visual>
      <origin xyz="0 0 0.08"/>
      <geometry>
        <box size="0.5 0.35 0.16"/>
      </geometry>
      <material name="blue">
        <color rgba="0 0.5 1 1"/>
      </material>
    </visual>

    <collision>
      <origin xyz="0 0 0.08"/>
      <geometry>
        <box size="0.48 0.33 0.14"/>
      </geometry>
    </collision>

    <inertial>
      <origin xyz="0 0 0.08"/>
      <mass value="8.0"/>
      <inertia ixx="0.15" ixy="0" ixz="0" 
               iyy="0.20" iyz="0" izz="0.25"/>
    </inertial>
  </link>

  <joint name="base_joint" type="fixed">
    <parent link="base_footprint"/>
    <child link="base_link"/>
    <origin xyz="0 0 0.1"/>
  </joint>

  <!-- LEFT WHEEL - AT THE BACK -->
  <link name="left_wheel">
    <visual>
      <origin rpy="1.5708 0 0"/>
      <geometry>
        <cylinder radius="0.1" length="0.05"/>
      </geometry>
      <material name="black">
        <color rgba="0.1 0.1 0.1 1"/>
      </material>
    </visual>

    <collision>
      <origin rpy="1.5708 0 0"/>
      <geometry>
        <cylinder radius="0.1" length="0.05"/>
      </geometry>
    </collision>

    <inertial>
      <origin rpy="1.5708 0 0"/>
      <mass value="1.0"/>
      <inertia ixx="0.003" ixy="0" ixz="0" 
               iyy="0.003" iyz="0" izz="0.005"/>
    </inertial>
  </link>

  <joint name="left_wheel_joint" type="continuous">
    <parent link="base_link"/>
    <child link="left_wheel"/>
    <origin xyz="-0.15 0.20 0"/>
    <axis xyz="0 1 0"/>
  </joint>

  <!-- RIGHT WHEEL - AT THE BACK -->
  <link name="right_wheel">
    <visual>
      <origin rpy="1.5708 0 0"/>
      <geometry>
        <cylinder radius="0.1" length="0.05"/>
      </geometry>
      <material name="black">
        <color rgba="0.1 0.1 0.1 1"/>
      </material>
    </visual>

    <collision>
      <origin rpy="1.5708 0 0"/>
      <geometry>
        <cylinder radius="0.1" length="0.05"/>
      </geometry>
    </collision>

    <inertial>
      <origin rpy="1.5708 0 0"/>
      <mass value="1.0"/>
      <inertia ixx="0.003" ixy="0" ixz="0" 
               iyy="0.003" iyz="0" izz="0.005"/>
    </inertial>
  </link>

  <joint name="right_wheel_joint" type="continuous">
    <parent link="base_link"/>
    <child link="right_wheel"/>
    <origin xyz="-0.15 -0.20 0"/>
    <axis xyz="0 1 0"/>
  </joint>

  <!-- CASTER - AT THE FRONT -->
  <link name="caster_wheel">
    <visual>
      <geometry>
        <sphere radius="0.06"/>
      </geometry>
      <material name="grey">
        <color rgba="0.5 0.5 0.5 1"/>
      </material>
    </visual>

    <collision>
      <geometry>
        <sphere radius="0.06"/>
      </geometry>
    </collision>

    <inertial>
      <mass value="0.5"/>
      <inertia ixx="0.0007" ixy="0" ixz="0" 
               iyy="0.0007" iyz="0" izz="0.0007"/>
    </inertial>
  </link>

  <joint name="caster_joint" type="fixed">
    <parent link="base_link"/>
    <child link="caster_wheel"/>
    <origin xyz="0.20 0 -0.04"/>
  </joint>

  <!-- LIDAR -->
  <link name="lidar_link">
    <visual>
      <geometry>
        <cylinder length="0.05" radius="0.05"/>
      </geometry>
      <material name="red">
        <color rgba="1 0 0 1"/>
      </material>
    </visual>

    <collision>
      <geometry>
        <cylinder length="0.05" radius="0.05"/>
      </geometry>
    </collision>

    <inertial>
      <mass value="0.2"/>
      <inertia ixx="0.0002" ixy="0" ixz="0" 
               iyy="0.0002" iyz="0" izz="0.0002"/>
    </inertial>
  </link>

  <joint name="lidar_joint" type="fixed">
    <parent link="base_link"/>
    <child link="lidar_link"/>
    <origin xyz="0 0 0.18"/>
  </joint>

  <!-- GAZEBO MATERIALS -->
  <gazebo reference="base_link">
    <material>Gazebo/Blue</material>
  </gazebo>

  <gazebo reference="left_wheel">
    <material>Gazebo/Black</material>
    <mu1>1.0</mu1>
    <mu2>1.0</mu2>
    <kp>1000000.0</kp>
    <kd>100.0</kd>
    <minDepth>0.005</minDepth>
  </gazebo>

  <gazebo reference="right_wheel">
    <material>Gazebo/Black</material>
    <mu1>1.0</mu1>
    <mu2>1.0</mu2>
    <kp>1000000.0</kp>
    <kd>100.0</kd>
    <minDepth>0.005</minDepth>
  </gazebo>

  <gazebo reference="caster_wheel">
    <material>Gazebo/Grey</material>
    <mu1>0.01</mu1>
    <mu2>0.01</mu2>
    <kp>1000000.0</kp>
    <kd>10.0</kd>
    <minDepth>0.005</minDepth>
  </gazebo>

  <gazebo reference="lidar_link">
    <material>Gazebo/Red</material>
  </gazebo>

  <!-- DIFFERENTIAL DRIVE PLUGIN -->
  <gazebo>
    <plugin name="diff_drive" filename="libgazebo_ros_diff_drive.so">
      <update_rate>50</update_rate>
      
      <left_joint>left_wheel_joint</left_joint>
      <right_joint>right_wheel_joint</right_joint>
      
      <wheel_separation>0.40</wheel_separation>
      <wheel_diameter>0.20</wheel_diameter>
      
      <max_wheel_torque>20</max_wheel_torque>
      <max_wheel_acceleration>2.0</max_wheel_acceleration>
      
      <command_topic>cmd_vel</command_topic>
      <odometry_topic>odom</odometry_topic>
      
      <publish_odom>true</publish_odom>
      <publish_odom_tf>true</publish_odom_tf>
      <publish_wheel_tf>false</publish_wheel_tf>
      
      <odometry_frame>odom</odometry_frame>
      <robot_base_frame>base_footprint</robot_base_frame>
      
      <odometry_source>world</odometry_source>
    </plugin>
  </gazebo>

  <!-- LIDAR SENSOR -->
  <gazebo reference="lidar_link">
    <sensor name="lidar" type="ray">
      <always_on>true</always_on>
      <update_rate>10</update_rate>
      <visualize>true</visualize>
      
      <ray>
        <scan>
          <horizontal>
            <samples>360</samples>
            <resolution>1</resolution>
            <min_angle>-1.04719</min_angle>
            <max_angle>1.04719</max_angle>
          </horizontal>
        </scan>
        <range>
          <min>0.15</min>
          <max>5.0</max>
          <resolution>0.01</resolution>
        </range>
        <noise>
          <type>gaussian</type>
          <mean>0.0</mean>
          <stddev>0.01</stddev>
        </noise>
      </ray>
      
      <plugin name="scan_plugin" filename="libgazebo_ros_ray_sensor.so">
        <ros>
          <namespace>/</namespace>
          <remapping>~/out:=scan</remapping>
        </ros>
        <output_type>sensor_msgs/LaserScan</output_type>
        <frame_name>lidar_link</frame_name>
      </plugin>
    </sensor>
  </gazebo>

</robot>
